<?xml version="1.0" ?>
<!-- =================================================================================== -->
<!-- |    This document was autogenerated by xacro from braccio.xacro                  | -->
<!-- |    EDITING THIS FILE BY HAND IS NOT RECOMMENDED                                 | -->
<!-- =================================================================================== -->
<robot name="braccio_arm" xmlns:xacro="http://ros.org/wiki/xacro">
  <!-- links -->
  <link name="braccio_base_link">
    <visual>
      <origin rpy="0 0 0" xyz="0 0 0"/>
      <geometry>
        <mesh filename="package://braccio_support/meshes/visual/base_plate.stl"/>
      </geometry>
      <material name="">
        <color rgba="0.811764705882 0.309803921569 0.0 1.0"/>
      </material>
    </visual>
    <collision>
      <origin rpy="0 0 0" xyz="0 0 0"/>
      <geometry>
        <mesh filename="package://braccio_support/meshes/collision/base_plate.stl"/>
      </geometry>
    </collision>
  </link>
  <link name="braccio_link_1">
    <visual>
      <origin rpy="0 0 0" xyz="0 0 0.0 0.0"/>
      <geometry>
        <mesh filename="package://braccio_support/meshes/visual/base_plate.stl"/>
      </geometry>
      <material name="">
        <color rgba="0.811764705882 0.309803921569 0.0 1.0"/>
      </material>
    </visual>
    <collision>
      <origin rpy="0 0 0" xyz="0 0 0"/>
      <geometry>
        <mesh filename="package://braccio_support/meshes/collision/base_plate.stl"/>
      </geometry>
    </collision>
  </link>
  <link name="braccio_tool0"/>
  <!-- joints -->
  <joint name="braccio_joint_1" type="revolute">
    <origin rpy="0 0 0" xyz="0 0 0.004"/>
    <parent link="braccio_base_link"/>
    <child link="braccio_link_1"/>
    <axis xyz="0 0 1"/>
    <limit effort="0" lower="-3.14" upper="3.14" velocity="3.67"/>
  </joint>
  <!--    <joint name="${prefix}joint_2" type="revolute">-->
  <!--      <origin xyz="0.150 0 0" rpy="0 0 0"/>-->
  <!--      <parent link="${prefix}link_1"/>-->
  <!--      <child link="${prefix}link_2"/>-->
  <!--      <axis xyz="0 1 0"/>-->
  <!--      <limit lower="-1.57" upper="2.79" effort="0" velocity="3.32"/>-->
  <!--    </joint>-->
  <!--    <joint name="${prefix}joint_3" type="revolute">-->
  <!--      <origin xyz="0 0 0.600" rpy="0 0 0"/>-->
  <!--      <parent link="${prefix}link_2"/>-->
  <!--      <child link="${prefix}link_3"/>-->
  <!--      <axis xyz="0 -1 0"/>-->
  <!--      <limit lower="-3.14" upper="4.61" effort="0" velocity="3.67"/>-->
  <!--    </joint>-->
  <!--    <joint name="${prefix}joint_4" type="revolute">-->
  <!--      <origin xyz="0 0 0.200" rpy="0 0 0"/>-->
  <!--      <parent link="${prefix}link_3"/>-->
  <!--      <child link="${prefix}link_4"/>-->
  <!--      <axis xyz="-1 0 0"/>-->
  <!--      <limit lower="-3.31" upper="3.31" effort="0" velocity="6.98"/>-->
  <!--    </joint>-->
  <!--    <joint name="${prefix}joint_5" type="revolute">-->
  <!--      <origin xyz="0.640 0 0" rpy="0 0 0"/>-->
  <!--      <parent link="${prefix}link_4"/>-->
  <!--      <child link="${prefix}link_5"/>-->
  <!--      <axis xyz="0 -1 0"/>-->
  <!--      <limit lower="-3.31" upper="3.31" effort="0" velocity="6.98"/>-->
  <!--    </joint>-->
  <!--    <joint name="${prefix}joint_6" type="revolute">-->
  <!--      <origin xyz="0.100 0 0" rpy="0 0 0"/>-->
  <!--      <parent link="${prefix}link_5"/>-->
  <!--      <child link="${prefix}link_6"/>-->
  <!--      <axis xyz="-1 0 0"/>-->
  <!--      <limit lower="-6.28" upper="6.28" effort="0" velocity="10.47"/>-->
  <!--    </joint>-->
  <!--    <joint name="${prefix}joint_6-tool0" type="fixed">-->
  <!--      <origin xyz="0 0 0" rpy="${m_pi} ${-m_pi_2} 0" />-->
  <!--      <parent link="${prefix}link_6"/>-->
  <!--      <child link="${prefix}tool0"/>-->
  <!--    </joint>-->
  <!-- ROS base_link to Fanuc World Coordinates transform -->
  <link name="braccio_base"/>
  <joint name="braccio_base_link-base" type="fixed">
    <origin rpy="0 0 0" xyz="0 0 0.0"/>
    <parent link="base_link"/>
    <child link="braccio_base"/>
  </joint>
</robot>

