<?xml version="1.0"?>
<robot xmlns:xacro="http://ros.org/wiki/xacro">
  <xacro:include filename="$(find braccio_support)/urdf/materials.xacro"/>
  <xacro:include filename="$(find braccio_support)/urdf/constants.xacro"/>

  <xacro:macro name="braccio_arm" params="prefix">
    <!-- links -->
    <link name="${prefix}_base">
      <visual>
        <origin xyz="0 0 0" rpy="0 0 0"/>
        <geometry>
          <mesh filename="package://braccio_support/meshes/visual/base_plate.stl"/>
        </geometry>
        <xacro:material_body />
      </visual>
      <collision>
        <origin xyz="0 0 0" rpy="0 0 0"/>
        <geometry>
          <mesh filename="package://braccio_support/meshes/collision/base_plate.stl"/>
        </geometry>
      </collision>
    </link>
    
    <link name="${prefix}_link_1">
      <visual>
        <origin xyz="0 0 ${-7.22+0.01}" rpy="0 0 0"/>
        <geometry>
          <mesh filename="package://braccio_support/meshes/visual/base_m1.stl"/>
        </geometry>
        <xacro:material_body />
      </visual>
      <collision>
        <origin xyz="0 0 ${-7.22+0.01}" rpy="0 0 0"/>
        <geometry>
          <mesh filename="package://braccio_support/meshes/collision/base_m1.stl"/>
        </geometry>
      </collision>
    </link>
    
    <link name="${prefix}_link_2">
      <visual>
        <origin xyz="0 0 2.45" rpy="0 0 ${-m_pi_2}"/> 
        <geometry>
          <mesh filename="package://braccio_support/meshes/visual/arm_m23.stl"/>
        </geometry>
        <xacro:material_body />
      </visual>
      <collision>
        <origin xyz="0 0 2.45" rpy="0 0 ${-m_pi_2}"/>
        <geometry>
          <mesh filename="package://braccio_support/meshes/collision/arm_m23.stl"/>
        </geometry>
      </collision>
    </link>
    
    <link name="${prefix}_link_3">
      <visual>
        <origin xyz="0 0 2.45" rpy="0 0 ${-m_pi_2}"/>
        <geometry>
          <mesh filename="package://braccio_support/meshes/visual/arm_m23.stl"/>
        </geometry>
        <xacro:material_body />
      </visual>
      <collision>
        <origin xyz="0 0 2.45" rpy="0 0 ${-m_pi_2}"/>
        <geometry>
          <mesh filename="package://braccio_support/meshes/collision/arm_m23.stl"/>
        </geometry>
      </collision>
    </link>
    
    <link name="${prefix}_link_4">
      <visual>
        <origin xyz="2 -0.475 0" rpy="0 ${m_pi_2} 0"/>
        <geometry>
          <mesh filename="package://braccio_support/meshes/visual/hand.stl"/>
        </geometry>
        <xacro:material_body />
      </visual>
      <collision>
        <origin xyz="2 -0.475 0" rpy="0 ${m_pi_2} 0"/>
        <geometry>
          <mesh filename="package://braccio_support/meshes/collision/hand.stl"/>
        </geometry>
      </collision>
    </link>
    
    <link name="${prefix}_link_5">
      <visual>
        <origin xyz="0 0 0" rpy="0 0 0"/>
        <geometry>
          <mesh filename="package://braccio_support/meshes/visual/gripper.stl"/>
        </geometry>
        <xacro:material_gripper />
      </visual>
      <collision>
        <origin xyz="0 0 0" rpy="0 0 0"/>
        <geometry>
          <mesh filename="package://braccio_support/meshes/collision/gripper.stl"/>
        </geometry>
      </collision>
    </link>
    
    <link name="${prefix}_ee"/>

    <!-- joints -->
    <!-- ROS base_link to Braccio World Coordinates transform -->
    <link name="base_link" />
    <joint name="${prefix}_base_link-base" type="fixed">
      <origin xyz="0 0 0" rpy="0 0 0"/>
      <parent link="base_link"/>
      <child link="${prefix}_base"/>
    </joint>
    
    <joint name="${prefix}_joint_1" type="revolute">
      <origin xyz="0 0 7.22" rpy="0 0 0"/>
      <parent link="${prefix}_base"/>
      <child link="${prefix}_link_1"/>
      <axis xyz="0 0 1"/>
      <limit lower="0" upper="3.12" effort="0" velocity="3.67"/>
    </joint>
    
    <joint name="${prefix}_joint_2" type="revolute">
      <origin xyz="0 0 0" rpy="0 ${-m_pi_2} 0"/> 
      <parent link="${prefix}_link_1"/>
      <child link="${prefix}_link_2"/>
      <axis xyz="0 0 1"/>
      <limit lower="0.26" upper="2.88" effort="0" velocity="3.67"/>
    </joint>
    
    <joint name="${prefix}_joint_3" type="revolute">
      <origin xyz="12.5 0 0" rpy="0 0 0"/>
      <parent link="${prefix}_link_2"/>
      <child link="${prefix}_link_3"/>
      <axis xyz="0 0 1"/>
      <limit lower="0" upper="3.14" effort="0" velocity="3.67"/>
    </joint>
    
    <joint name="${prefix}_joint_4" type="revolute">
      <origin xyz="12.5 0 0" rpy="0 0 0"/>
      <parent link="${prefix}_link_3"/>
      <child link="${prefix}_link_4"/>
      <axis xyz="0 0 1"/>
      <limit lower="0" upper="3.14" effort="0" velocity="3.67"/>
    </joint>
    
    <joint name="${prefix}_joint_5" type="revolute">
      <origin xyz="6.1 0 0" rpy="0 ${m_pi_2} 0" />
      <parent link="${prefix}_link_4"/>
      <child link="${prefix}_link_5"/>
      <axis xyz="0 0 1"/>
      <limit lower="0" upper="3.14" effort="0" velocity="3.67"/>
    </joint>
    
    <joint name="${prefix}_joint_ee" type="fixed">
      <origin xyz="0 0.45 ${3.4+9.2}" rpy="0 0 0" />
      <parent link="${prefix}_link_5"/>
      <child link="${prefix}_ee"/>
    </joint>
    
  </xacro:macro>
</robot>
